Workbook
Name UPDATE: 'Data Sheet'!$E$1

Sheet One-Page
B2: UltraTech Cement - One Page Profile
C4: UltraTech Cement Limited is the cement flagship company of the Aditya Birla Group. A USD 8.9 billion building solutions powerhouse, UltraTech is the largest manufacturer of grey cement and ready-mix concrete (RMC) and one of the largest manufacturers of white cement in India. It is the second largest cement company globally by capacity and the largest by sales volume (excluding China).
B6: Key Financial Metrics | C6: =Historical_FS!H10 -> 44286 | D6: =Historical_FS!I10 -> 44651 | E6: =Historical_FS!J10 -> 45016 | F6: =Historical_FS!K10 -> 45382 | G6: =Historical_FS!L10 -> 45747 | I6: Share Price - 5Y
B8: Total Sales | C8: =Historical_FS!H12 -> 44725.8 | D8: =Historical_FS!I12 -> 52598.83 | E8: =Historical_FS!J12 -> 63239.98 | F8: =Historical_FS!K12 -> 70908.14 | G8: =Historical_FS!L12 -> 75955.13
B9: Sales Growth | C9: =Historical_FS!H13 -> 0.054110675 | D9: =Historical_FS!I13 -> 0.17602882 | E9: =Historical_FS!J13 -> 0.20230773 | F9: =Historical_FS!K13 -> 0.12125494 | G9: =Historical_FS!L13 -> 0.071176454
B10: Gross Profit Margin (%) | C10: =Historical_FS!H22 -> 0.54770669 | D10: =Historical_FS!I22 -> 0.50821168 | E10: =Historical_FS!J22 -> 0.44979711 | F10: =Historical_FS!K22 -> 0.47002643 | G10: =Historical_FS!L22 -> 0.46257745
B11: EBITDA Margin (%) | C11: =Historical_FS!H28 -> 0.2724698 | D11: =Historical_FS!I28 -> 0.23163595 | E11: =Historical_FS!J28 -> 0.17594819 | F11: =Historical_FS!K28 -> 0.1908881 | G11: =Historical_FS!L28 -> 0.17370282
B12: EBIT Margin (%) | C12: =Historical_FS!H34 -> 0.21209682 | D12: =Historical_FS!I34 -> 0.18002359 | E12: =Historical_FS!J34 -> 0.13028103 | F12: =Historical_FS!K34 -> 0.14653071 | G12: =Historical_FS!L34 -> 0.12084332
B13: Net Profit Margin (%) | C13: =Historical_FS!H46 -> 0.12211855 | D13: =Historical_FS!I46 -> 0.1394377 | E13: =Historical_FS!J46 -> 0.080224567 | F13: =Historical_FS!K46 -> 0.098775119 | G13: =Historical_FS!L46 -> 0.079515893
B14: Earnings Per Share (In Rs.) | C14: =Historical_FS!H50 -> 189.18774 | D14: =Historical_FS!I50 -> 254.04434 | E14: =Historical_FS!J50 -> 175.73259 | F14: =Historical_FS!K50 -> 242.60339 | G14: =Historical_FS!L50 -> 204.94197
B15: EPS Growth | C15: =Historical_FS!H51 -> -0.050587367 | D15: =Historical_FS!I51 -> 0.34281608 | E15: =Historical_FS!J51 -> -0.30826014 | F15: =Historical_FS!K51 -> 0.38052588 | G15: =Historical_FS!L51 -> -0.15523863
B16: Dividend Per Share (In Rs.) | C16: =Historical_FS!H54 -> 36.993419 | D16: =Historical_FS!I54 -> 37.99619 | E16: =Historical_FS!J54 -> 37.998614 | F16: =Historical_FS!K54 -> 69.997575 | G16: =Historical_FS!L54 -> 77.49474
B17: DPS Growth | C17: =Historical_FS!H55 -> 1.8453442 | D17: =Historical_FS!I55 -> 0.027106742 | E17: =Historical_FS!J55 -> 6.3813301e-05 | F17: =Historical_FS!K55 -> 0.84210862 | G17: =Historical_FS!L55 -> 0.10710607
B19: Key Financial Ratios | C19: =C6 -> 44286 | D19: =D6 -> 44651 | E19: =E6 -> 45016 | F19: =F6 -> 45382 | G19: =G6 -> 45747 | I19: Volume - 5Y
B21: Price to Earnings | C21: 35.58 | D21: 25.93 | E21: 43.4 | F21: 40.96 | G21: ='Relative_Val.'!P16 -> 47.50985
B22: EV/EBITDA | C22: 17.66 | D22: 16.7 | E22: 22.6 | F22: 24.2 | G22: ='Relative_Val.'!O16 -> 23.578018
B23: EV/Sales | C23: 4.82 | D23: 3.93 | E23: 3.75 | F23: 4.2 | G23: ='Relative_Val.'!N16 -> 4.530178
B24: Price to Book Value | C24: 4.8 | D24: 4.1 | E24: 4.3 | F24: 5 | G24: 5.4
B25: Return on Equity (%) | C25: =Ratios!H28 -> 0.1236421 | D25: =Ratios!I28 -> 0.14541927 | E25: =Ratios!J28 -> 0.093390574 | F25: =Ratios!K28 -> 0.11629177 | G25: =Ratios!L28 -> 0.085418129
B26: Return on Capital Employed (%) | C26: =Ratios!H26 -> 0.14396136 | D26: =Ratios!I26 -> 0.15338418 | E26: =Ratios!J26 -> 0.12601228 | F26: =Ratios!K26 -> 0.14505316 | G26: =Ratios!L26 -> 0.096812274
B28: Top 10 Shareholders | C28: No. of Shares (In Cr.) | E28: % Holding | F28: Market Value (In Cr.) | I28: Latest Shareholding
B30: ='Comps Rel.'!Q3 -> Grasim Industries Limited | C30: ='Comps Rel.'!R3 -> 16.533515 | E30: ='Comps Rel.'!S3 -> 0.5611 | F30: ='Comps Rel.'!T3 -> 197360.57
B31: ='Comps Rel.'!Q4 -> LIFE INSURANCE CORPORATION OF INDIA | C31: ='Comps Rel.'!R4 -> 0.6104355 | E31: ='Comps Rel.'!S4 -> 0.0207 | F31: ='Comps Rel.'!T4 -> 7286.7686
B32: ='Comps Rel.'!Q5 -> ICICI PRUDENTIAL NIFTY INFRASTRUCTURE ETF | C32: ='Comps Rel.'!R5 -> 0.6038328 | E32: ='Comps Rel.'!S5 -> 0.0205 | F32: ='Comps Rel.'!T5 -> 7207.9521
B33: ='Comps Rel.'!Q6 -> NPS TRUST-A/C TATA PENSION FUND MANAGEMENT PRIVATE | C33: ='Comps Rel.'!R6 -> 0.5769186 | E33: ='Comps Rel.'!S6 -> 0.0196 | F33: ='Comps Rel.'!T6 -> 6886.6773
B34: ='Comps Rel.'!Q7 -> Pilani Investment and Industries Corporation Limited | C34: ='Comps Rel.'!R7 -> 0.4405944 | E34: ='Comps Rel.'!S7 -> 0.015 | F34: ='Comps Rel.'!T7 -> 5259.3754
B35: ='Comps Rel.'!Q8 -> SBI NIFTY 50 EQUAL WEIGHT INDEX FUND | C35: ='Comps Rel.'!R8 -> 0.4310567 | E35: ='Comps Rel.'!S8 -> 0.0146 | F35: ='Comps Rel.'!T8 -> 5145.5238
B36: ='Comps Rel.'!Q9 -> Government of Singapore - E | C36: ='Comps Rel.'!R9 -> 0.3937328 | E36: ='Comps Rel.'!S9 -> 0.0134 | F36: ='Comps Rel.'!T9 -> 4699.9884
B37: ='Comps Rel.'!Q10 -> KOTAK AGGRESSIVE HYBRID FUND | C37: ='Comps Rel.'!R10 -> 0.3256356 | E37: ='Comps Rel.'!S10 -> 0.0111 | F37: ='Comps Rel.'!T10 -> 3887.1122
B38: ='Comps Rel.'!Q11 -> PT. Indo Bharat Rayon | C38: ='Comps Rel.'!R11 -> 0.2286172 | E38: ='Comps Rel.'!S11 -> 0.0078 | F38: ='Comps Rel.'!T11 -> 2729.0035
B39: ='Comps Rel.'!Q12 -> Hindalco Industries Limited | C39: ='Comps Rel.'!R12 -> 0.1258515 | E39: ='Comps Rel.'!S12 -> 0.0043 | F39: ='Comps Rel.'!T12 -> 1502.2894
B41: Managerial Remuneration (In Cr.) | C41: Designation | E41: Remuneration | F41: X of Median Salary | I41: Capital Structure
B43: Kumar Mangalam Birla | C43: Chairman | E43: 0.043 | F43: - | I43: Share Price as on 10-01-25 | K43: =DCF!E49 -> 11937
B44: K. K. Maheshwari | C44: Vice Chairman | E44: 0.45 | F44: - | I44: Number of Shares o/s | K44: =DCF!E45 -> 29.490848
B45: Mrs. Rajashree Birla | C45: Non-Executive Director | E45: 6.727 | F45: 88.8 | I45: Market Capitalization | K45: =K43*K44 -> 352032.26
B46: K. C. Jhanwar | C46: Managing Director | E46: =13.42+5.26 -> 18.68 | F46: 247.5 | I46: Less: Cash & Equivalents | K46: =DCF!E42 -> 1673.32
B47: Atul Daga | C47: Whole Time Director & CFO | E47: =6.6+2.56 -> 9.16 | F47: 121.4 | I47: Add: Total Debt | K47: =DCF!E43 -> 23031
I48: Add: Minority Interest | K48: 55.94
I49: Enterprise Value | K49: =K45+K47+K48-K46 -> 373445.88
B51: Recent Updates

Sheet Historical_FS
B9: ="Financial Statements"&" - "&'Data Sheet'!B1 -> Financial Statements - ULTRATECH CEMENT LTD
B10: Years | C10: ='Data Sheet'!B16 -> 42460 | D10: ='Data Sheet'!C16 -> 42825 | E10: ='Data Sheet'!D16 -> 43190 | F10: ='Data Sheet'!E16 -> 43555 | G10: ='Data Sheet'!F16 -> 43921 | H10: ='Data Sheet'!G16 -> 44286 | I10: ='Data Sheet'!H16 -> 44651 | J10: ='Data Sheet'!I16 -> 45016 | ... L10: ='Data Sheet'!K16 -> 45747
A11: # | B11: Income Statement
B12: Sales | C12: =IFERROR('Data Sheet'!B17,0) -> 25153.24 | D12: =IFERROR('Data Sheet'!C17,0) -> 25374.94 | E12: =IFERROR('Data Sheet'!D17,0) -> 30978.62 | F12: =IFERROR('Data Sheet'!E17,0) -> 41462.26 | G12: =IFERROR('Data Sheet'!F17,0) -> 42429.89 | H12: =IFERROR('Data Sheet'!G17,0) -> 44725.8 | I12: =IFERROR('Data Sheet'!H17,0) -> 52598.83 | J12: =IFERROR('Data Sheet'!I17,0) -> 63239.98 | ... L12: =IFERROR('Data Sheet'!K17,0) -> 75955.13
B13: =B12&" Growth" -> Sales Growth | C13: =IFERROR((C12/B12)-1,"-") -> - | D13: =IFERROR((D12/C12)-1,"-") -> 0.0088139739 | E13: =IFERROR((E12/D12)-1,"-") -> 0.2208352 | F13: =IFERROR((F12/E12)-1,"-") -> 0.33841533 | G13: =IFERROR((G12/F12)-1,"-") -> 0.023337609 | H13: =IFERROR((H12/G12)-1,"-") -> 0.054110675 | I13: =IFERROR((I12/H12)-1,"-") -> 0.17602882 | J13: =IFERROR((J12/I12)-1,"-") -> 0.20230773 | ... L13: =IFERROR((L12/K12)-1,"-") -> 0.071176454
B15: Other Income | C15: =IFERROR('Data Sheet'!B25,0) -> 463.81 | D15: =IFERROR('Data Sheet'!C25,0) -> 648.12 | E15: =IFERROR('Data Sheet'!D25,0) -> 241.97 | F15: =IFERROR('Data Sheet'!E25,0) -> 350.1 | G15: =IFERROR('Data Sheet'!F25,0) -> 651.06 | H15: =IFERROR('Data Sheet'!G25,0) -> 618.52 | I15: =IFERROR('Data Sheet'!H25,0) -> 669.43 | J15: =IFERROR('Data Sheet'!I25,0) -> 507.11 | ... L15: =IFERROR('Data Sheet'!K25,0) -> 396.74
B16: =B15&" % Sales" -> Other Income % Sales | C16: =IFERROR(C15/C$12,0) -> 0.018439374 | D16: =IFERROR(D15/D$12,0) -> 0.025541735 | E16: =IFERROR(E15/E$12,0) -> 0.0078108709 | F16: =IFERROR(F15/F$12,0) -> 0.0084438234 | G16: =IFERROR(G15/G$12,0) -> 0.015344372 | H16: =IFERROR(H15/H$12,0) -> 0.013829155 | I16: =IFERROR(I15/I$12,0) -> 0.012727089 | J16: =IFERROR(J15/J$12,0) -> 0.0080188197 | ... L16: =IFERROR(L15/L$12,0) -> 0.005223347
B18: COGS | C18: =IFERROR(SUM('Data Sheet'!B18,'Data Sheet'!B20:B22)-1*('Data Sheet'!B19),0) -> 12397.13 | D18: =IFERROR(SUM('Data Sheet'!C18,'Data Sheet'!C20:C22)-1*('Data Sheet'!C19),0) -> 12303.62 | E18: =IFERROR(SUM('Data Sheet'!D18,'Data Sheet'!D20:D22)-1*('Data Sheet'!D19),0) -> 15744.19 | F18: =IFERROR(SUM('Data Sheet'!E18,'Data Sheet'!E20:E22)-1*('Data Sheet'!E19),0) -> 21729.72 | G18: =IFERROR(SUM('Data Sheet'!F18,'Data Sheet'!F20:F22)-1*('Data Sheet'!F19),0) -> 20600.87 | H18: =IFERROR(SUM('Data Sheet'!G18,'Data Sheet'!G20:G22)-1*('Data Sheet'!G19),0) -> 20847.7 | I18: =IFERROR(SUM('Data Sheet'!H18,'Data Sheet'!H20:H22)-1*('Data Sheet'!H19),0) -> 26536.92 | J18: =IFERROR(SUM('Data Sheet'!I18,'Data Sheet'!I20:I22)-1*('Data Sheet'!I19),0) -> 35301.93 | ... L18: =IFERROR(SUM('Data Sheet'!K18,'Data Sheet'!K20:K22)-1*('Data Sheet'!K19),0) -> 41216.74
B19: =B18&" % Sales" -> COGS % Sales | C19: =IFERROR(C18/C12,0) -> 0.49286414 | D19: =IFERROR(D18/D12,0) -> 0.48487287 | E19: =IFERROR(E18/E12,0) -> 0.50822761 | F19: =IFERROR(F18/F12,0) -> 0.52408431 | G19: =IFERROR(G18/G12,0) -> 0.4855273 | H19: =IFERROR(H18/H12,0) -> 0.46612246 | I19: =IFERROR(I18/I12,0) -> 0.5045154 | J19: =IFERROR(J18/J12,0) -> 0.55822171 | ... L19: =IFERROR(L18/L12,0) -> 0.5426459
B21: Gross Profit | C21: =IFERROR(C12+C15-C18,0) -> 13219.92 | D21: =IFERROR(D12+D15-D18,0) -> 13719.44 | E21: =IFERROR(E12+E15-E18,0) -> 15476.4 | F21: =IFERROR(F12+F15-F18,0) -> 20082.64 | G21: =IFERROR(G12+G15-G18,0) -> 22480.08 | H21: =IFERROR(H12+H15-H18,0) -> 24496.62 | I21: =IFERROR(I12+I15-I18,0) -> 26731.34 | J21: =IFERROR(J12+J15-J18,0) -> 28445.16 | ... L21: =IFERROR(L12+L15-L18,0) -> 35135.13
B22: =B21&" % Sales" -> Gross Profit % Sales | C22: =IFERROR(C21/C12,0) -> 0.52557523 | D22: =IFERROR(D21/D12,0) -> 0.54066886 | E22: =IFERROR(E21/E12,0) -> 0.49958326 | F22: =IFERROR(F21/F12,0) -> 0.48435951 | G22: =IFERROR(G21/G12,0) -> 0.52981707 | H22: =IFERROR(H21/H12,0) -> 0.54770669 | I22: =IFERROR(I21/I12,0) -> 0.50821168 | J22: =IFERROR(J21/J12,0) -> 0.44979711 | ... L22: =IFERROR(L21/L12,0) -> 0.46257745
B24: Selling & Other Exp. | C24: =IFERROR(SUM('Data Sheet'!B23:B24),0) -> 7855.14 | D24: =IFERROR(SUM('Data Sheet'!C23:C24),0) -> 7858.88 | E24: =IFERROR(SUM('Data Sheet'!D23:D24),0) -> 9089.4 | F24: =IFERROR(SUM('Data Sheet'!E23:E24),0) -> 12385.6 | G24: =IFERROR(SUM('Data Sheet'!F23:F24),0) -> 12583.05 | H24: =IFERROR(SUM('Data Sheet'!G23:G24),0) -> 12310.19 | I24: =IFERROR(SUM('Data Sheet'!H23:H24),0) -> 14547.56 | J24: =IFERROR(SUM('Data Sheet'!I23:I24),0) -> 17318.2 | ... L24: =IFERROR(SUM('Data Sheet'!K23:K24),0) -> 21941.51
B25: =B24&" % Sales" -> Selling & Other Exp. % Sales | C25: =IFERROR(C24/C12,0) -> 0.31229138 | D25: =IFERROR(D24/D12,0) -> 0.30971029 | E25: =IFERROR(E24/E12,0) -> 0.29340881 | F25: =IFERROR(F24/F12,0) -> 0.29871985 | G25: =IFERROR(G24/G12,0) -> 0.29656099 | H25: =IFERROR(H24/H12,0) -> 0.27523689 | I25: =IFERROR(I24/I12,0) -> 0.27657573 | J25: =IFERROR(J24/J12,0) -> 0.27384892 | ... L25: =IFERROR(L24/L12,0) -> 0.28887463
B27: EBITDA | C27: =IFERROR(C21-C24,0) -> 5364.78 | D27: =IFERROR(D21-D24,0) -> 5860.56 | E27: =IFERROR(E21-E24,0) -> 6387 | F27: =IFERROR(F21-F24,0) -> 7697.04 | G27: =IFERROR(G21-G24,0) -> 9897.03 | H27: =IFERROR(H21-H24,0) -> 12186.43 | I27: =IFERROR(I21-I24,0) -> 12183.78 | J27: =IFERROR(J21-J24,0) -> 11126.96 | ... L27: =IFERROR(L21-L24,0) -> 13193.62
B28: =B27&" % Sales" -> EBITDA % Sales | C28: =IFERROR(C27/C12,0) -> 0.21328386 | D28: =IFERROR(D27/D12,0) -> 0.23095858 | E28: =IFERROR(E27/E12,0) -> 0.20617445 | F28: =IFERROR(F27/F12,0) -> 0.18563966 | G28: =IFERROR(G27/G12,0) -> 0.23325608 | H28: =IFERROR(H27/H12,0) -> 0.2724698 | I28: =IFERROR(I27/I12,0) -> 0.23163595 | J28: =IFERROR(J27/J12,0) -> 0.17594819 | ... L28: =IFERROR(L27/L12,0) -> 0.17370282
B30: Depreciation | C30: =IFERROR('Data Sheet'!B26,0) -> 1377.17 | D30: =IFERROR('Data Sheet'!C26,0) -> 1348.41 | E30: =IFERROR('Data Sheet'!D26,0) -> 1847.93 | F30: =IFERROR('Data Sheet'!E26,0) -> 2450.73 | G30: =IFERROR('Data Sheet'!F26,0) -> 2722.66 | H30: =IFERROR('Data Sheet'!G26,0) -> 2700.23 | I30: =IFERROR('Data Sheet'!H26,0) -> 2714.75 | J30: =IFERROR('Data Sheet'!I26,0) -> 2887.99 | ... L30: =IFERROR('Data Sheet'!K26,0) -> 4014.95
B31: =B30&" % Sales" -> Depreciation % Sales | C31: =IFERROR(C30/C12,0) -> 0.054751197 | D31: =IFERROR(D30/D12,0) -> 0.053139436 | E31: =IFERROR(E30/E12,0) -> 0.059651786 | F31: =IFERROR(F30/F12,0) -> 0.059107487 | G31: =IFERROR(G30/G12,0) -> 0.064168444 | H31: =IFERROR(H30/H12,0) -> 0.060372984 | I31: =IFERROR(I30/I12,0) -> 0.051612365 | J31: =IFERROR(J30/J12,0) -> 0.045667155 | ... L31: =IFERROR(L30/L12,0) -> 0.052859497
B33: EBIT | C33: =IFERROR(C27-C30,0) -> 3987.61 | D33: =IFERROR(D27-D30,0) -> 4512.15 | E33: =IFERROR(E27-E30,0) -> 4539.07 | F33: =IFERROR(F27-F30,0) -> 5246.31 | G33: =IFERROR(G27-G30,0) -> 7174.37 | H33: =IFERROR(H27-H30,0) -> 9486.2 | I33: =IFERROR(I27-I30,0) -> 9469.03 | J33: =IFERROR(J27-J30,0) -> 8238.97 | ... L33: =IFERROR(L27-L30,0) -> 9178.67
B34: =B33&" % Sales" -> EBIT % Sales | C34: =IFERROR(C33/C12,0) -> 0.15853266 | D34: =IFERROR(D33/D12,0) -> 0.17781914 | E34: =IFERROR(E33/E12,0) -> 0.14652267 | F34: =IFERROR(F33/F12,0) -> 0.12653218 | G34: =IFERROR(G33/G12,0) -> 0.16908764 | H34: =IFERROR(H33/H12,0) -> 0.21209682 | I34: =IFERROR(I33/I12,0) -> 0.18002359 | J34: =IFERROR(J33/J12,0) -> 0.13028103 | ... L34: =IFERROR(L33/L12,0) -> 0.12084332
B36: Interest | C36: =IFERROR('Data Sheet'!B27,0) -> 566.3 | D36: =IFERROR('Data Sheet'!C27,0) -> 640.1 | E36: =IFERROR('Data Sheet'!D27,0) -> 1237.6 | F36: =IFERROR('Data Sheet'!E27,0) -> 1777.86 | G36: =IFERROR('Data Sheet'!F27,0) -> 1991.65 | H36: =IFERROR('Data Sheet'!G27,0) -> 1485.65 | I36: =IFERROR('Data Sheet'!H27,0) -> 944.71 | J36: =IFERROR('Data Sheet'!I27,0) -> 822.72 | ... L36: =IFERROR('Data Sheet'!K27,0) -> 1650.54
B37: =B36&" % Sales" -> Interest % Sales | C37: =IFERROR(C36/C12,0) -> 0.022513998 | D37: =IFERROR(D36/D12,0) -> 0.025225675 | E37: =IFERROR(E36/E12,0) -> 0.039950133 | F37: =IFERROR(F36/F12,0) -> 0.042878994 | G37: =IFERROR(G36/G12,0) -> 0.046939787 | H37: =IFERROR(H36/H12,0) -> 0.033216846 | I37: =IFERROR(I36/I12,0) -> 0.017960666 | J37: =IFERROR(J36/J12,0) -> 0.013009492 | ... L37: =IFERROR(L36/L12,0) -> 0.021730461
B39: EBT | C39: =IFERROR(C33-C36,0) -> 3421.31 | D39: =IFERROR(D33-D36,0) -> 3872.05 | E39: =IFERROR(E33-E36,0) -> 3301.47 | F39: =IFERROR(F33-F36,0) -> 3468.45 | G39: =IFERROR(G33-G36,0) -> 5182.72 | H39: =IFERROR(H33-H36,0) -> 8000.55 | I39: =IFERROR(I33-I36,0) -> 8524.32 | J39: =IFERROR(J33-J36,0) -> 7416.25 | ... L39: =IFERROR(L33-L36,0) -> 7528.13
B40: =B39&" % Sales" -> EBT % Sales | C40: =IFERROR(C39/C12,0) -> 0.13601866 | D40: =IFERROR(D39/D12,0) -> 0.15259346 | E40: =IFERROR(E39/E12,0) -> 0.10657253 | F40: =IFERROR(F39/F12,0) -> 0.083653182 | G40: =IFERROR(G39/G12,0) -> 0.12214785 | H40: =IFERROR(H39/H12,0) -> 0.17887998 | I40: =IFERROR(I39/I12,0) -> 0.16206292 | J40: =IFERROR(J39/J12,0) -> 0.11727154 | ... L40: =IFERROR(L39/L12,0) -> 0.099112858
B42: Tax | C42: =IFERROR('Data Sheet'!B29,0) -> 941.69 | D42: =IFERROR('Data Sheet'!C29,0) -> 1158.54 | E42: =IFERROR('Data Sheet'!D29,0) -> 1077.01 | F42: =IFERROR('Data Sheet'!E29,0) -> 1068.07 | G42: =IFERROR('Data Sheet'!F29,0) -> -568.16 | H42: =IFERROR('Data Sheet'!G29,0) -> 2538.7 | I42: =IFERROR('Data Sheet'!H29,0) -> 1190.06 | J42: =IFERROR('Data Sheet'!I29,0) -> 2342.85 | ... L42: =IFERROR('Data Sheet'!K29,0) -> 1488.49
B43: Effective Tax Rate | C43: =IFERROR(C42/C39,0) -> 0.27524252 | D43: =IFERROR(D42/D39,0) -> 0.29920585 | E43: =IFERROR(E42/E39,0) -> 0.32622135 | F43: =IFERROR(F42/F39,0) -> 0.3079387 | G43: =IFERROR(G42/G39,0) -> -0.10962583 | H43: =IFERROR(H42/H39,0) -> 0.31731568 | I43: =IFERROR(I42/I39,0) -> 0.13960762 | J43: =IFERROR(J42/J39,0) -> 0.31590764 | ... L43: =IFERROR(L42/L39,0) -> 0.19772374
B45: Net Profit | C45: =IFERROR(C39-C42,0) -> 2479.62 | D45: =IFERROR(D39-D42,0) -> 2713.51 | E45: =IFERROR(E39-E42,0) -> 2224.46 | F45: =IFERROR(F39-F42,0) -> 2400.38 | G45: =IFERROR(G39-G42,0) -> 5750.88 | H45: =IFERROR(H39-H42,0) -> 5461.85 | I45: =IFERROR(I39-I42,0) -> 7334.26 | J45: =IFERROR(J39-J42,0) -> 5073.4 | ... L45: =IFERROR(L39-L42,0) -> 6039.64
B46: =B45&" % Sales" -> Net Profit % Sales | C46: =IFERROR(C45/C12,0) -> 0.098580541 | D46: =IFERROR(D45/D12,0) -> 0.10693661 | E46: =IFERROR(E45/E12,0) -> 0.071806297 | F46: =IFERROR(F45/F12,0) -> 0.05789313 | G46: =IFERROR(G45/G12,0) -> 0.13553841 | H46: =IFERROR(H45/H12,0) -> 0.12211855 | I46: =IFERROR(I45/I12,0) -> 0.1394377 | J46: =IFERROR(J45/J12,0) -> 0.080224567 | ... L46: =IFERROR(L45/L12,0) -> 0.079515893
B48: No. of Equity Shares | C48: =IFERROR('Data Sheet'!B93,0) -> 27.44 | D48: =IFERROR('Data Sheet'!C93,0) -> 27.45 | E48: =IFERROR('Data Sheet'!D93,0) -> 27.46 | F48: =IFERROR('Data Sheet'!E93,0) -> 27.46 | G48: =IFERROR('Data Sheet'!F93,0) -> 28.86 | H48: =IFERROR('Data Sheet'!G93,0) -> 28.87 | I48: =IFERROR('Data Sheet'!H93,0) -> 28.87 | J48: =IFERROR('Data Sheet'!I93,0) -> 28.87 | ... L48: =IFERROR('Data Sheet'!K93,0) -> 29.47
B50: Earnings Per Share | C50: =IFERROR(C45/C48,0) -> 90.36516 | D50: =IFERROR(D45/D48,0) -> 98.852823 | E50: =IFERROR(E45/E48,0) -> 81.007283 | F50: =IFERROR(F45/F48,0) -> 87.413693 | G50: =IFERROR(G45/G48,0) -> 199.26819 | H50: =IFERROR(H45/H48,0) -> 189.18774 | I50: =IFERROR(I45/I48,0) -> 254.04434 | J50: =IFERROR(J45/J48,0) -> 175.73259 | ... L50: =IFERROR(L45/L48,0) -> 204.94197
B51: =B50&" Growth" -> Earnings Per Share Growth | C51: =IFERROR(C50/ABS(B50)-1,"-") -> - | D51: =IFERROR(D50/ABS(C50)-1,"-") -> 0.093926276 | E51: =IFERROR(E50/ABS(D50)-1,"-") -> -0.18052636 | F51: =IFERROR(F50/ABS(E50)-1,"-") -> 0.079084362 | G51: =IFERROR(G50/ABS(F50)-1,"-") -> 1.2795993 | H51: =IFERROR(H50/ABS(G50)-1,"-") -> -0.050587367 | I51: =IFERROR(I50/ABS(H50)-1,"-") -> 0.34281608 | J51: =IFERROR(J50/ABS(I50)-1,"-") -> -0.30826014 | ... L51: =IFERROR(L50/ABS(K50)-1,"-") -> -0.15523863
D52: =IFERROR(IF(AND(C50<0,D50>0),"Profit Swing",IF(AND(C50>0,D50<0),"Loss-Making",IF(C50=0,"-","-"))),0) -> - | E52: =IFERROR(IF(AND(D50<0,E50>0),"Profit Swing",IF(AND(D50>0,E50<0),"Loss-Making",IF(D50=0,"-","-"))),0) -> - | F52: =IFERROR(IF(AND(E50<0,F50>0),"Profit Swing",IF(AND(E50>0,F50<0),"Loss-Making",IF(E50=0,"-","-"))),0) -> - | G52: =IFERROR(IF(AND(F50<0,G50>0),"Profit Swing",IF(AND(F50>0,G50<0),"Loss-Making",IF(F50=0,"-","-"))),0) -> - | H52: =IFERROR(IF(AND(G50<0,H50>0),"Profit Swing",IF(AND(G50>0,H50<0),"Loss-Making",IF(G50=0,"-","-"))),0) -> - | I52: =IFERROR(IF(AND(H50<0,I50>0),"Profit Swing",IF(AND(H50>0,I50<0),"Loss-Making",IF(H50=0,"-","-"))),0) -> - | J52: =IFERROR(IF(AND(I50<0,J50>0),"Profit Swing",IF(AND(I50>0,J50<0),"Loss-Making",IF(I50=0,"-","-"))),0) -> - | K52: =IFERROR(IF(AND(J50<0,K50>0),"Profit Swing",IF(AND(J50>0,K50<0),"Loss-Making",IF(J50=0,"-","-"))),0) -> - | L52: =IFERROR(IF(AND(K50<0,L50>0),"Profit Swing",IF(AND(K50>0,L50<0),"Loss-Making",IF(K50=0,"-","-"))),0) -> -
B54: Dividend Per Share | C54: =IFERROR('Data Sheet'!B31/Historical_FS!C48,0) -> 9.5010933 | D54: =IFERROR('Data Sheet'!C31/Historical_FS!D48,0) -> 10.000364 | E54: =IFERROR('Data Sheet'!D31/Historical_FS!E48,0) -> 10.500364 | F54: =IFERROR('Data Sheet'!E31/Historical_FS!F48,0) -> 11.501821 | G54: =IFERROR('Data Sheet'!F31/Historical_FS!G48,0) -> 13.001386 | H54: =IFERROR('Data Sheet'!G31/Historical_FS!H48,0) -> 36.993419 | I54: =IFERROR('Data Sheet'!H31/Historical_FS!I48,0) -> 37.99619 | J54: =IFERROR('Data Sheet'!I31/Historical_FS!J48,0) -> 37.998614 | ... L54: =IFERROR('Data Sheet'!K31/Historical_FS!L48,0) -> 77.49474
B55: DPS Growth | C55: =IFERROR(C54/ABS(B54)-1,"-") -> - | D55: =IFERROR(D54/ABS(C54)-1,"-") -> 0.052548795 | E55: =IFERROR(E54/ABS(D54)-1,"-") -> 0.049998165 | F55: =IFERROR(F54/ABS(E54)-1,"-") -> 0.095373517 | G55: =IFERROR(G54/ABS(F54)-1,"-") -> 0.13037633 | H55: =IFERROR(H54/ABS(G54)-1,"-") -> 1.8453442 | I55: =IFERROR(I54/ABS(H54)-1,"-") -> 0.027106742 | J55: =IFERROR(J54/ABS(I54)-1,"-") -> 6.3813301e-05 | ... L55: =IFERROR(L54/ABS(K54)-1,"-") -> 0.10710607
B56: Dividend Payout Ratio | C56: =IFERROR(C54/C50,0) -> 0.10514111 | D56: =IFERROR(D54/D50,0) -> 0.10116417 | E56: =IFERROR(E54/E50,0) -> 0.12962247 | F56: =IFERROR(F54/F50,0) -> 0.13157917 | G56: =IFERROR(G54/G50,0) -> 0.065245667 | H56: =IFERROR(H54/H50,0) -> 0.19553814 | I56: =IFERROR(I54/I50,0) -> 0.14956519 | J56: =IFERROR(J54/J50,0) -> 0.21622975 | ... L56: =IFERROR(L54/L50,0) -> 0.37813015
B57: Retained Earnings | C57: =IFERROR(IF(C50>C54,1-C56,0),0) -> 0.89485889 | D57: =IFERROR(IF(D50>D54,1-D56,0),0) -> 0.89883583 | E57: =IFERROR(IF(E50>E54,1-E56,0),0) -> 0.87037753 | F57: =IFERROR(IF(F50>F54,1-F56,0),0) -> 0.86842083 | G57: =IFERROR(IF(G50>G54,1-G56,0),0) -> 0.93475433 | H57: =IFERROR(IF(H50>H54,1-H56,0),0) -> 0.80446186 | I57: =IFERROR(IF(I50>I54,1-I56,0),0) -> 0.85043481 | J57: =IFERROR(IF(J50>J54,1-J56,0),0) -> 0.78377025 | ... L57: =IFERROR(IF(L50>L54,1-L56,0),0) -> 0.62186985
A59: # | B59: Balance Sheet
B60: Equity & Liabilities
B61: Equity Share Capital | C61: =IFERROR('Data Sheet'!B57,0) -> 274.43 | D61: =IFERROR('Data Sheet'!C57,0) -> 274.51 | E61: =IFERROR('Data Sheet'!D57,0) -> 274.61 | F61: =IFERROR('Data Sheet'!E57,0) -> 274.64 | G61: =IFERROR('Data Sheet'!F57,0) -> 288.63 | H61: =IFERROR('Data Sheet'!G57,0) -> 288.65 | I61: =IFERROR('Data Sheet'!H57,0) -> 288.67 | J61: =IFERROR('Data Sheet'!I57,0) -> 288.69 | ... L61: =IFERROR('Data Sheet'!K57,0) -> 294.68
B62: Reserves | C62: =IFERROR('Data Sheet'!B58,0) -> 21671.2 | D62: =IFERROR('Data Sheet'!C58,0) -> 24117.38 | E62: =IFERROR('Data Sheet'!D58,0) -> 26106.55 | F62: =IFERROR('Data Sheet'!E58,0) -> 33476.01 | G62: =IFERROR('Data Sheet'!F58,0) -> 38755.13 | H62: =IFERROR('Data Sheet'!G58,0) -> 43886.03 | I62: =IFERROR('Data Sheet'!H58,0) -> 50146.6 | J62: =IFERROR('Data Sheet'!I58,0) -> 54035.85 | ... L62: =IFERROR('Data Sheet'!K58,0) -> 70412.09
B63: Borrowings | C63: =IFERROR('Data Sheet'!B59,0) -> 10615.99 | D63: =IFERROR('Data Sheet'!C59,0) -> 8474.49 | E63: =IFERROR('Data Sheet'!D59,0) -> 19480.22 | F63: =IFERROR('Data Sheet'!E59,0) -> 25337 | G63: =IFERROR('Data Sheet'!F59,0) -> 23018.96 | H63: =IFERROR('Data Sheet'!G59,0) -> 21719.39 | I63: =IFERROR('Data Sheet'!H59,0) -> 11298.8 | J63: =IFERROR('Data Sheet'!I59,0) -> 11057.74 | ... L63: =IFERROR('Data Sheet'!K59,0) -> 24102.18
...

Sheet Ratios
B9: ="Ratio Analysis"&" - "&'Data Sheet'!B1 -> Ratio Analysis - ULTRATECH CEMENT LTD
B10: Years | C10: ='Data Sheet'!B16 -> 42460 | D10: ='Data Sheet'!C16 -> 42825 | E10: ='Data Sheet'!D16 -> 43190 | F10: ='Data Sheet'!E16 -> 43555 | G10: ='Data Sheet'!F16 -> 43921 | H10: ='Data Sheet'!G16 -> 44286 | I10: ='Data Sheet'!H16 -> 44651 | J10: ='Data Sheet'!I16 -> 45016 | ... L10: ='Data Sheet'!K16 -> 45747 | M10: Trend
B12: Gross Profit Margin | C12: =IFERROR(Historical_FS!C22,0) -> 0.52557523 | D12: =IFERROR(Historical_FS!D22,0) -> 0.54066886 | E12: =IFERROR(Historical_FS!E22,0) -> 0.49958326 | F12: =IFERROR(Historical_FS!F22,0) -> 0.48435951 | G12: =IFERROR(Historical_FS!G22,0) -> 0.52981707 | H12: =IFERROR(Historical_FS!H22,0) -> 0.54770669 | I12: =IFERROR(Historical_FS!I22,0) -> 0.50821168 | J12: =IFERROR(Historical_FS!J22,0) -> 0.44979711 | ... L12: =IFERROR(Historical_FS!L22,0) -> 0.46257745
B13: EBITDA Margin | C13: =IFERROR(Historical_FS!C28,0) -> 0.21328386 | D13: =IFERROR(Historical_FS!D28,0) -> 0.23095858 | E13: =IFERROR(Historical_FS!E28,0) -> 0.20617445 | F13: =IFERROR(Historical_FS!F28,0) -> 0.18563966 | G13: =IFERROR(Historical_FS!G28,0) -> 0.23325608 | H13: =IFERROR(Historical_FS!H28,0) -> 0.2724698 | I13: =IFERROR(Historical_FS!I28,0) -> 0.23163595 | J13: =IFERROR(Historical_FS!J28,0) -> 0.17594819 | ... L13: =IFERROR(Historical_FS!L28,0) -> 0.17370282
B14: EBIT Margin | C14: =IFERROR(Historical_FS!C34,) -> 0.15853266 | D14: =IFERROR(Historical_FS!D34,) -> 0.17781914 | E14: =IFERROR(Historical_FS!E34,) -> 0.14652267 | F14: =IFERROR(Historical_FS!F34,) -> 0.12653218 | G14: =IFERROR(Historical_FS!G34,) -> 0.16908764 | H14: =IFERROR(Historical_FS!H34,) -> 0.21209682 | I14: =IFERROR(Historical_FS!I34,) -> 0.18002359 | J14: =IFERROR(Historical_FS!J34,) -> 0.13028103 | ... L14: =IFERROR(Historical_FS!L34,) -> 0.12084332
B15: EBT Margin | C15: =IFERROR(Historical_FS!C40,0) -> 0.13601866 | D15: =IFERROR(Historical_FS!D40,0) -> 0.15259346 | E15: =IFERROR(Historical_FS!E40,0) -> 0.10657253 | F15: =IFERROR(Historical_FS!F40,0) -> 0.083653182 | G15: =IFERROR(Historical_FS!G40,0) -> 0.12214785 | H15: =IFERROR(Historical_FS!H40,0) -> 0.17887998 | I15: =IFERROR(Historical_FS!I40,0) -> 0.16206292 | J15: =IFERROR(Historical_FS!J40,0) -> 0.11727154 | ... L15: =IFERROR(Historical_FS!L40,0) -> 0.099112858
B16: Net Profit Margin | C16: =IFERROR(Historical_FS!C46,) -> 0.098580541 | D16: =IFERROR(Historical_FS!D46,) -> 0.10693661 | E16: =IFERROR(Historical_FS!E46,) -> 0.071806297 | F16: =IFERROR(Historical_FS!F46,) -> 0.05789313 | G16: =IFERROR(Historical_FS!G46,) -> 0.13553841 | H16: =IFERROR(Historical_FS!H46,) -> 0.12211855 | I16: =IFERROR(Historical_FS!I46,) -> 0.1394377 | J16: =IFERROR(Historical_FS!J46,) -> 0.080224567 | ... L16: =IFERROR(Historical_FS!L46,) -> 0.079515893
B18: Current Ratio | C18: =IFERROR(Historical_FS!C78/Historical_FS!C64,0) -> 0.7704058 | D18: =IFERROR(Historical_FS!D78/Historical_FS!D64,0) -> 0.68572141 | E18: =IFERROR(Historical_FS!E78/Historical_FS!E64,0) -> 0.50597843 | F18: =IFERROR(Historical_FS!F78/Historical_FS!F64,0) -> 0.43730889 | G18: =IFERROR(Historical_FS!G78/Historical_FS!G64,0) -> 0.41434568 | H18: =IFERROR(Historical_FS!H78/Historical_FS!H64,0) -> 0.42387986 | I18: =IFERROR(Historical_FS!I78/Historical_FS!I64,0) -> 0.40885169 | J18: =IFERROR(Historical_FS!J78/Historical_FS!J64,0) -> 0.44728003 | ... L18: =IFERROR(Historical_FS!L78/Historical_FS!L64,0) -> 0.44114317
B19: Quick Ratio | C19: =IFERROR((Historical_FS!C78-Historical_FS!C76)/Historical_FS!C64,0) -> 0.4860308 | D19: =IFERROR((Historical_FS!D78-Historical_FS!D76)/Historical_FS!D64,0) -> 0.42876868 | E19: =IFERROR((Historical_FS!E78-Historical_FS!E76)/Historical_FS!E64,0) -> 0.21629102 | F19: =IFERROR((Historical_FS!F78-Historical_FS!F76)/Historical_FS!F64,0) -> 0.20224605 | G19: =IFERROR((Historical_FS!G78-Historical_FS!G76)/Historical_FS!G64,0) -> 0.17043407 | H19: =IFERROR((Historical_FS!H78-Historical_FS!H76)/Historical_FS!H64,0) -> 0.22577738 | I19: =IFERROR((Historical_FS!I78-Historical_FS!I76)/Historical_FS!I64,0) -> 0.15539849 | J19: =IFERROR((Historical_FS!J78-Historical_FS!J76)/Historical_FS!J64,0) -> 0.19296049 | ... L19: =IFERROR((Historical_FS!L78-Historical_FS!L76)/Historical_FS!L64,0) -> 0.19482133
B20: Cash Ratio | C20: =IFERROR(Historical_FS!C77/Historical_FS!C64,0) -> 0.26263832 | D20: =IFERROR(Historical_FS!D77/Historical_FS!D64,0) -> 0.24069838 | E20: =IFERROR(Historical_FS!E77/Historical_FS!E64,0) -> 0.019421599 | F20: =IFERROR(Historical_FS!F77/Historical_FS!F64,0) -> 0.04241839 | G20: =IFERROR(Historical_FS!G77/Historical_FS!G64,0) -> 0.031479632 | H20: =IFERROR(Historical_FS!H77/Historical_FS!H64,0) -> 0.098980489 | I20: =IFERROR(Historical_FS!I77/Historical_FS!I64,0) -> 0.016269148 | J20: =IFERROR(Historical_FS!J77/Historical_FS!J64,0) -> 0.044218197 | ... L20: =IFERROR(Historical_FS!L77/Historical_FS!L64,0) -> 0.043101132
B22: Debt to Equity Ratio | C22: =IFERROR(SUM(Historical_FS!C63:C64)/SUM(Historical_FS!C61:C62),0) -> 0.87705297 | D22: =IFERROR(SUM(Historical_FS!D63:D64)/SUM(Historical_FS!D61:D62),0) -> 0.73045672 | E22: =IFERROR(SUM(Historical_FS!E63:E64)/SUM(Historical_FS!E61:E62),0) -> 1.165981 | F22: =IFERROR(SUM(Historical_FS!F63:F64)/SUM(Historical_FS!F61:F62),0) -> 1.2673747 | G22: =IFERROR(SUM(Historical_FS!G63:G64)/SUM(Historical_FS!G61:G62),0) -> 1.0288469 | H22: =IFERROR(SUM(Historical_FS!H63:H64)/SUM(Historical_FS!H61:H62),0) -> 0.9508087 | I22: =IFERROR(SUM(Historical_FS!I63:I64)/SUM(Historical_FS!I61:I62),0) -> 0.66176249 | J22: =IFERROR(SUM(Historical_FS!J63:J64)/SUM(Historical_FS!J61:J62),0) -> 0.68212009 | ... L22: =IFERROR(SUM(Historical_FS!L63:L64)/SUM(Historical_FS!L61:L62),0) -> 0.88994717
B23: Debt to Assets Ratio | C23: =IFERROR(SUM(Historical_FS!C63:C64)/Historical_FS!C80,0) -> 0.46724998 | D23: =IFERROR(SUM(Historical_FS!D63:D64)/Historical_FS!D80,0) -> 0.42211788 | E23: =IFERROR(SUM(Historical_FS!E63:E64)/Historical_FS!E80,0) -> 0.53831542 | F23: =IFERROR(SUM(Historical_FS!F63:F64)/Historical_FS!F80,0) -> 0.5589613 | G23: =IFERROR(SUM(Historical_FS!G63:G64)/Historical_FS!G80,0) -> 0.50710918 | H23: =IFERROR(SUM(Historical_FS!H63:H64)/Historical_FS!H80,0) -> 0.48739207 | I23: =IFERROR(SUM(Historical_FS!I63:I64)/Historical_FS!I80,0) -> 0.39822929 | J23: =IFERROR(SUM(Historical_FS!J63:J64)/Historical_FS!J80,0) -> 0.40551212 | ... L23: =IFERROR(SUM(Historical_FS!L63:L64)/Historical_FS!L80,0) -> 0.47088468
B24: Interest Coverage Ratio | C24: =IFERROR(Historical_FS!C33/Historical_FS!C36,0) -> 7.0415151 | D24: =IFERROR(Historical_FS!D33/Historical_FS!D36,0) -> 7.0491329 | E24: =IFERROR(Historical_FS!E33/Historical_FS!E36,0) -> 3.667639 | F24: =IFERROR(Historical_FS!F33/Historical_FS!F36,0) -> 2.9509129 | G24: =IFERROR(Historical_FS!G33/Historical_FS!G36,0) -> 3.6022243 | H24: =IFERROR(Historical_FS!H33/Historical_FS!H36,0) -> 6.3852186 | I24: =IFERROR(Historical_FS!I33/Historical_FS!I36,0) -> 10.023213 | J24: =IFERROR(Historical_FS!J33/Historical_FS!J36,0) -> 10.014306 | ... L24: =IFERROR(Historical_FS!L33/Historical_FS!L36,0) -> 5.5610103
B26: Return on Capital Employed | C26: =IFERROR(Historical_FS!C33/SUM(Historical_FS!C61:C63),0) -> 0.1224635 | D26: =IFERROR(Historical_FS!D33/SUM(Historical_FS!D61:D63),0) -> 0.13728771 | E26: =IFERROR(Historical_FS!E33/SUM(Historical_FS!E61:E63),0) -> 0.09897369 | F26: =IFERROR(Historical_FS!F33/SUM(Historical_FS!F61:F63),0) -> 0.088788605 | G26: =IFERROR(Historical_FS!G33/SUM(Historical_FS!G61:G63),0) -> 0.1155987 | H26: =IFERROR(Historical_FS!H33/SUM(Historical_FS!H61:H63),0) -> 0.14396136 | I26: =IFERROR(Historical_FS!I33/SUM(Historical_FS!I61:I63),0) -> 0.15338418 | J26: =IFERROR(Historical_FS!J33/SUM(Historical_FS!J61:J63),0) -> 0.12601228 | ... L26: =IFERROR(Historical_FS!L33/SUM(Historical_FS!L61:L63),0) -> 0.096812274
B27: Retained Earnings % | C27: =IFERROR(Historical_FS!C57,0) -> 0.89485889 | D27: =IFERROR(Historical_FS!D57,0) -> 0.89883583 | E27: =IFERROR(Historical_FS!E57,0) -> 0.87037753 | F27: =IFERROR(Historical_FS!F57,0) -> 0.86842083 | G27: =IFERROR(Historical_FS!G57,0) -> 0.93475433 | H27: =IFERROR(Historical_FS!H57,0) -> 0.80446186 | I27: =IFERROR(Historical_FS!I57,0) -> 0.85043481 | J27: =IFERROR(Historical_FS!J57,0) -> 0.78377025 | ... L27: =IFERROR(Historical_FS!L57,0) -> 0.62186985
B28: Return on Equity % | C28: =IFERROR(Historical_FS!C45/SUM(Historical_FS!C61:C62),0) -> 0.11298924 | D28: =IFERROR(Historical_FS!D45/SUM(Historical_FS!D61:D62),0) -> 0.1112464 | E28: =IFERROR(Historical_FS!E45/SUM(Historical_FS!E61:E62),0) -> 0.084320022 | F28: =IFERROR(Historical_FS!F45/SUM(Historical_FS!F61:F62),0) -> 0.071121001 | G28: =IFERROR(Historical_FS!G45/SUM(Historical_FS!G61:G62),0) -> 0.14729319 | H28: =IFERROR(Historical_FS!H45/SUM(Historical_FS!H61:H62),0) -> 0.1236421 | I28: =IFERROR(Historical_FS!I45/SUM(Historical_FS!I61:I62),0) -> 0.14541927 | J28: =IFERROR(Historical_FS!J45/SUM(Historical_FS!J61:J62),0) -> 0.093390574 | ... L28: =IFERROR(Historical_FS!L45/SUM(Historical_FS!L61:L62),0) -> 0.085418129
B29: Self Sustained Growth Rate | C29: =IFERROR(C28*C27,0) -> 0.10110942 | D29: =IFERROR(D28*D27,0) -> 0.099992252 | E29: =IFERROR(E28*E27,0) -> 0.073390253 | F29: =IFERROR(F28*F27,0) -> 0.061762959 | G29: =IFERROR(G28*G27,0) -> 0.13768295 | H29: =IFERROR(H28*H27,0) -> 0.09946535 | I29: =IFERROR(I28*I27,0) -> 0.12366961 | J29: =IFERROR(J28*J27,0) -> 0.073196754 | ... L29: =IFERROR(L28*L27,0) -> 0.053118959
B31: Debtor Turnover Ratio | C31: =IFERROR(Historical_FS!C12/Historical_FS!C75,0) -> 13.044865 | D31: =IFERROR(Historical_FS!D12/Historical_FS!D75,0) -> 14.441457 | E31: =IFERROR(Historical_FS!E12/Historical_FS!E75,0) -> 13.950374 | F31: =IFERROR(Historical_FS!F12/Historical_FS!F75,0) -> 14.876862 | G31: =IFERROR(Historical_FS!G12/Historical_FS!G75,0) -> 17.803598 | H31: =IFERROR(Historical_FS!H12/Historical_FS!H75,0) -> 17.391328 | I31: =IFERROR(Historical_FS!I12/Historical_FS!I75,0) -> 17.124189 | J31: =IFERROR(Historical_FS!J12/Historical_FS!J75,0) -> 16.353673 | ... L31: =IFERROR(Historical_FS!L12/Historical_FS!L75,0) -> 12.89506
B32: Creditor Turnover Ratio | C32: =IFERROR((Historical_FS!C18+Historical_FS!C76)/Historical_FS!C64,0) -> 1.7206427 | D32: =IFERROR((Historical_FS!D18+Historical_FS!D76)/Historical_FS!D64,0) -> 1.5738719 | E32: =IFERROR((Historical_FS!E18+Historical_FS!E76)/Historical_FS!E64,0) -> 1.6854848 | F32: =IFERROR((Historical_FS!F18+Historical_FS!F76)/Historical_FS!F64,0) -> 1.4811959 | G32: =IFERROR((Historical_FS!G18+Historical_FS!G76)/Historical_FS!G64,0) -> 1.4450522 | H32: =IFERROR((Historical_FS!H18+Historical_FS!H76)/Historical_FS!H64,0) -> 1.22598 | I32: =IFERROR((Historical_FS!I18+Historical_FS!I76)/Historical_FS!I64,0) -> 1.4554496 | J32: =IFERROR((Historical_FS!J18+Historical_FS!J76)/Historical_FS!J64,0) -> 1.6121843 | ... L32: =IFERROR((Historical_FS!L18+Historical_FS!L76)/Historical_FS!L64,0) -> 1.3079766
B33: Inventory Turnover Ratio | C33: =IFERROR(Historical_FS!C18/Historical_FS!C76,0) -> 5.0506115 | D33: =IFERROR(Historical_FS!D18/Historical_FS!D76,0) -> 5.1251416 | E33: =IFERROR(Historical_FS!E18/Historical_FS!E76,0) -> 4.8182881 | F33: =IFERROR(Historical_FS!F18/Historical_FS!F76,0) -> 5.3012764 | G33: =IFERROR(Historical_FS!G18/Historical_FS!G76,0) -> 4.9244911 | H33: =IFERROR(Historical_FS!H18/Historical_FS!H76,0) -> 5.1886151 | I33: =IFERROR(Historical_FS!I18/Historical_FS!I76,0) -> 4.7424789 | J33: =IFERROR(Historical_FS!J18/Historical_FS!J76,0) -> 5.3392071 | ... L33: =IFERROR(Historical_FS!L18/Historical_FS!L76,0) -> 4.310031
B34: Fixed Asset Turnover Ratio | C34: =IFERROR(Historical_FS!C12/SUM(Historical_FS!C68:C70),0) -> 0.78915369 | D34: =IFERROR(Historical_FS!D12/SUM(Historical_FS!D68:D70),0) -> 0.75710517 | E34: =IFERROR(Historical_FS!E12/SUM(Historical_FS!E68:E70),0) -> 0.66373166 | F34: =IFERROR(Historical_FS!F12/SUM(Historical_FS!F68:F70),0) -> 0.68285175 | G34: =IFERROR(Historical_FS!G12/SUM(Historical_FS!G68:G70),0) -> 0.6629749 | H34: =IFERROR(Historical_FS!H12/SUM(Historical_FS!H68:H70),0) -> 0.6456138 | I34: =IFERROR(Historical_FS!I12/SUM(Historical_FS!I68:I70),0) -> 0.78967725 | J34: =IFERROR(Historical_FS!J12/SUM(Historical_FS!J68:J70),0) -> 0.89175471 | ... L34: =IFERROR(Historical_FS!L12/SUM(Historical_FS!L68:L70),0) -> 0.71686297
B35: Capital Turnover Ratio | C35: =IFERROR(Historical_FS!C12/SUM(Historical_FS!C61:C63),0) -> 0.77248122 | D35: =IFERROR(Historical_FS!D12/SUM(Historical_FS!D61:D63),0) -> 0.77206373 | E35: =IFERROR(Historical_FS!E12/SUM(Historical_FS!E61:E63),0) -> 0.67548382 | F35: =IFERROR(Historical_FS!F12/SUM(Historical_FS!F61:F63),0) -> 0.70170772 | G35: =IFERROR(Historical_FS!G12/SUM(Historical_FS!G61:G63),0) -> 0.68366146 | H35: =IFERROR(Historical_FS!H12/SUM(Historical_FS!H61:H63),0) -> 0.67875303 | I35: =IFERROR(Historical_FS!I12/SUM(Historical_FS!I61:I63),0) -> 0.85202272 | J35: =IFERROR(Historical_FS!J12/SUM(Historical_FS!J61:J63),0) -> 0.96723424 | ... L35: =IFERROR(Historical_FS!L12/SUM(Historical_FS!L61:L63),0) -> 0.80113882
B37: Debtor Days | C37: =IFERROR(365/C31,0) -> 27.980358 | D37: =IFERROR(365/D31,0) -> 25.274458 | E37: =IFERROR(365/E31,0) -> 26.164172 | F37: =IFERROR(365/F31,0) -> 24.534744 | G37: =IFERROR(365/G31,0) -> 20.501474 | H37: =IFERROR(365/H31,0) -> 20.987471 | I37: =IFERROR(365/I31,0) -> 21.314878 | J37: =IFERROR(365/J31,0) -> 22.319145 | ... L37: =IFERROR(365/L31,0) -> 28.305412
B38: Payable Days | C38: =IFERROR(365/C32,0) -> 212.13004 | D38: =IFERROR(365/D32,0) -> 231.91214 | E38: =IFERROR(365/E32,0) -> 216.5549 | F38: =IFERROR(365/F32,0) -> 246.4225 | G38: =IFERROR(365/G32,0) -> 252.58603 | H38: =IFERROR(365/H32,0) -> 297.721 | I38: =IFERROR(365/I32,0) -> 250.78161 | J38: =IFERROR(365/J32,0) -> 226.40092 | ... L38: =IFERROR(365/L32,0) -> 279.05698
B39: Inventory Days | C39: =IFERROR(365/C33,0) -> 72.268477 | D39: =IFERROR(365/D33,0) -> 71.217544 | E39: =IFERROR(365/E33,0) -> 75.753046 | F39: =IFERROR(365/F33,0) -> 68.851343 | G39: =IFERROR(365/G33,0) -> 74.119333 | H39: =IFERROR(365/H33,0) -> 70.346324 | I39: =IFERROR(365/I33,0) -> 76.963969 | J39: =IFERROR(365/J33,0) -> 68.36221 | ... L39: =IFERROR(365/L33,0) -> 84.686166
B40: Cash Conversion Cycle | C40: =IFERROR(C37+C39-C38,0) -> -111.88121 | D40: =IFERROR(D37+D39-D38,0) -> -135.42014 | E40: =IFERROR(E37+E39-E38,0) -> -114.63768 | F40: =IFERROR(F37+F39-F38,0) -> -153.03641 | G40: =IFERROR(G37+G39-G38,0) -> -157.96523 | H40: =IFERROR(H37+H39-H38,0) -> -206.38721 | I40: =IFERROR(I37+I39-I38,0) -> -152.50276 | J40: =IFERROR(J37+J39-J38,0) -> -135.71956 | ... L40: =IFERROR(L37+L39-L38,0) -> -166.0654
B42: CFO/Sales | C42: =IFERROR(Historical_FS!C86/Historical_FS!C12,0) -> 0.1798973 | D42: =IFERROR(Historical_FS!D86/Historical_FS!D12,0) -> 0.19724185 | E42: =IFERROR(Historical_FS!E86/Historical_FS!E12,0) -> 0.12550591 | F42: =IFERROR(Historical_FS!F86/Historical_FS!F12,0) -> 0.14364871 | G42: =IFERROR(Historical_FS!G86/Historical_FS!G12,0) -> 0.21147828 | H42: =IFERROR(Historical_FS!H86/Historical_FS!H12,0) -> 0.27948075 | I42: =IFERROR(Historical_FS!I86/Historical_FS!I12,0) -> 0.17648682 | J42: =IFERROR(Historical_FS!J86/Historical_FS!J12,0) -> 0.14340612 | ... L42: =IFERROR(Historical_FS!L86/Historical_FS!L12,0) -> 0.14051717
B43: CFO/Total Assets | C43: =IFERROR(Historical_FS!C86/Historical_FS!C80,0) -> 0.10984847 | D43: =IFERROR(Historical_FS!D86/Historical_FS!D80,0) -> 0.1185763 | E43: =IFERROR(Historical_FS!E86/Historical_FS!E80,0) -> 0.068042104 | F43: =IFERROR(Historical_FS!F86/Historical_FS!F80,0) -> 0.077830398 | G43: =IFERROR(Historical_FS!G86/Historical_FS!G80,0) -> 0.1132757 | H43: =IFERROR(Historical_FS!H86/Historical_FS!H80,0) -> 0.1450514 | I43: =IFERROR(Historical_FS!I86/Historical_FS!I80,0) -> 0.11076054 | J43: =IFERROR(Historical_FS!J86/Historical_FS!J80,0) -> 0.099244477 | ... L43: =IFERROR(Historical_FS!L86/Historical_FS!L80,0) -> 0.079868558
B44: CFO/Total Debt | C44: =IFERROR(Historical_FS!C86/Historical_FS!C63,0) -> 0.42624381 | D44: =IFERROR(Historical_FS!D86/Historical_FS!D63,0) -> 0.59059601 | E44: =IFERROR(Historical_FS!E86/Historical_FS!E63,0) -> 0.19958707 | F44: =IFERROR(Historical_FS!F86/Historical_FS!F63,0) -> 0.23507124 | G44: =IFERROR(Historical_FS!G86/Historical_FS!G63,0) -> 0.3898091 | H44: =IFERROR(Historical_FS!H86/Historical_FS!H63,0) -> 0.57552261 | I44: =IFERROR(Historical_FS!I86/Historical_FS!I63,0) -> 0.82159167 | J44: =IFERROR(Historical_FS!J86/Historical_FS!J63,0) -> 0.82014951 | ... L44: =IFERROR(Historical_FS!L86/Historical_FS!L63,0) -> 0.44282301

Sheet Vertical
B9: ="Vertical Analysis"&" - "&'Data Sheet'!B1 -> Vertical Analysis - ULTRATECH CEMENT LTD
B10: Years | C10: ='Data Sheet'!B16 -> 42460 | D10: ='Data Sheet'!C16 -> 42825 | E10: ='Data Sheet'!D16 -> 43190 | F10: ='Data Sheet'!E16 -> 43555 | G10: ='Data Sheet'!F16 -> 43921 | H10: ='Data Sheet'!G16 -> 44286 | I10: ='Data Sheet'!H16 -> 44651 | J10: ='Data Sheet'!I16 -> 45016 | ... L10: ='Data Sheet'!K16 -> 45747
A11: # | B11: Income Statement % Sales
B12: =Historical_FS!B12&" % Sales" -> Sales % Sales | C12: =IFERROR(Historical_FS!C12/Historical_FS!C12,0) -> 1 | D12: =IFERROR(Historical_FS!D12/Historical_FS!D12,0) -> 1 | E12: =IFERROR(Historical_FS!E12/Historical_FS!E12,0) -> 1 | F12: =IFERROR(Historical_FS!F12/Historical_FS!F12,0) -> 1 | G12: =IFERROR(Historical_FS!G12/Historical_FS!G12,0) -> 1 | H12: =IFERROR(Historical_FS!H12/Historical_FS!H12,0) -> 1 | I12: =IFERROR(Historical_FS!I12/Historical_FS!I12,0) -> 1 | J12: =IFERROR(Historical_FS!J12/Historical_FS!J12,0) -> 1 | ... L12: =IFERROR(Historical_FS!L12/Historical_FS!L12,0) -> 1
B14: =Historical_FS!B18&" % Sales" -> COGS % Sales | C14: =IFERROR(Historical_FS!C19,0) -> 0.49286414 | D14: =IFERROR(Historical_FS!D19,0) -> 0.48487287 | E14: =IFERROR(Historical_FS!E19,0) -> 0.50822761 | F14: =IFERROR(Historical_FS!F19,0) -> 0.52408431 | G14: =IFERROR(Historical_FS!G19,0) -> 0.4855273 | H14: =IFERROR(Historical_FS!H19,0) -> 0.46612246 | I14: =IFERROR(Historical_FS!I19,0) -> 0.5045154 | J14: =IFERROR(Historical_FS!J19,0) -> 0.55822171 | ... L14: =IFERROR(Historical_FS!L19,0) -> 0.5426459
B15: =Historical_FS!B21&" % Sales" -> Gross Profit % Sales | C15: =IFERROR(Historical_FS!C22,0) -> 0.52557523 | D15: =IFERROR(Historical_FS!D22,0) -> 0.54066886 | E15: =IFERROR(Historical_FS!E22,0) -> 0.49958326 | F15: =IFERROR(Historical_FS!F22,0) -> 0.48435951 | G15: =IFERROR(Historical_FS!G22,0) -> 0.52981707 | H15: =IFERROR(Historical_FS!H22,0) -> 0.54770669 | I15: =IFERROR(Historical_FS!I22,0) -> 0.50821168 | J15: =IFERROR(Historical_FS!J22,0) -> 0.44979711 | ... L15: =IFERROR(Historical_FS!L22,0) -> 0.46257745
B16: =Historical_FS!B24&" % Sales" -> Selling & Other Exp. % Sales | C16: =IFERROR(Historical_FS!C25,0) -> 0.31229138 | D16: =IFERROR(Historical_FS!D25,0) -> 0.30971029 | E16: =IFERROR(Historical_FS!E25,0) -> 0.29340881 | F16: =IFERROR(Historical_FS!F25,0) -> 0.29871985 | G16: =IFERROR(Historical_FS!G25,0) -> 0.29656099 | H16: =IFERROR(Historical_FS!H25,0) -> 0.27523689 | I16: =IFERROR(Historical_FS!I25,0) -> 0.27657573 | J16: =IFERROR(Historical_FS!J25,0) -> 0.27384892 | ... L16: =IFERROR(Historical_FS!L25,0) -> 0.28887463
B17: =Historical_FS!B27&" % Sales" -> EBITDA % Sales | C17: =IFERROR(Historical_FS!C28,0) -> 0.21328386 | D17: =IFERROR(Historical_FS!D28,0) -> 0.23095858 | E17: =IFERROR(Historical_FS!E28,0) -> 0.20617445 | F17: =IFERROR(Historical_FS!F28,0) -> 0.18563966 | G17: =IFERROR(Historical_FS!G28,0) -> 0.23325608 | H17: =IFERROR(Historical_FS!H28,0) -> 0.2724698 | I17: =IFERROR(Historical_FS!I28,0) -> 0.23163595 | J17: =IFERROR(Historical_FS!J28,0) -> 0.17594819 | ... L17: =IFERROR(Historical_FS!L28,0) -> 0.17370282
B18: =Historical_FS!B30&" % Sales" -> Depreciation % Sales | C18: =IFERROR(Historical_FS!C31,0) -> 0.054751197 | D18: =IFERROR(Historical_FS!D31,0) -> 0.053139436 | E18: =IFERROR(Historical_FS!E31,0) -> 0.059651786 | F18: =IFERROR(Historical_FS!F31,0) -> 0.059107487 | G18: =IFERROR(Historical_FS!G31,0) -> 0.064168444 | H18: =IFERROR(Historical_FS!H31,0) -> 0.060372984 | I18: =IFERROR(Historical_FS!I31,0) -> 0.051612365 | J18: =IFERROR(Historical_FS!J31,0) -> 0.045667155 | ... L18: =IFERROR(Historical_FS!L31,0) -> 0.052859497
B19: =Historical_FS!B33&" % Sales" -> EBIT % Sales | C19: =IFERROR(Historical_FS!C34,0) -> 0.15853266 | D19: =IFERROR(Historical_FS!D34,0) -> 0.17781914 | E19: =IFERROR(Historical_FS!E34,0) -> 0.14652267 | F19: =IFERROR(Historical_FS!F34,0) -> 0.12653218 | G19: =IFERROR(Historical_FS!G34,0) -> 0.16908764 | H19: =IFERROR(Historical_FS!H34,0) -> 0.21209682 | I19: =IFERROR(Historical_FS!I34,0) -> 0.18002359 | J19: =IFERROR(Historical_FS!J34,0) -> 0.13028103 | ... L19: =IFERROR(Historical_FS!L34,0) -> 0.12084332
B20: =Historical_FS!B36&" % Sales" -> Interest % Sales | C20: =IFERROR(Historical_FS!C37,0) -> 0.022513998 | D20: =IFERROR(Historical_FS!D37,0) -> 0.025225675 | E20: =IFERROR(Historical_FS!E37,0) -> 0.039950133 | F20: =IFERROR(Historical_FS!F37,0) -> 0.042878994 | G20: =IFERROR(Historical_FS!G37,0) -> 0.046939787 | H20: =IFERROR(Historical_FS!H37,0) -> 0.033216846 | I20: =IFERROR(Historical_FS!I37,0) -> 0.017960666 | J20: =IFERROR(Historical_FS!J37,0) -> 0.013009492 | ... L20: =IFERROR(Historical_FS!L37,0) -> 0.021730461
B21: =Historical_FS!B39&" % Sales" -> EBT % Sales | C21: =IFERROR(Historical_FS!C40,0) -> 0.13601866 | D21: =IFERROR(Historical_FS!D40,0) -> 0.15259346 | E21: =IFERROR(Historical_FS!E40,0) -> 0.10657253 | F21: =IFERROR(Historical_FS!F40,0) -> 0.083653182 | G21: =IFERROR(Historical_FS!G40,0) -> 0.12214785 | H21: =IFERROR(Historical_FS!H40,0) -> 0.17887998 | I21: =IFERROR(Historical_FS!I40,0) -> 0.16206292 | J21: =IFERROR(Historical_FS!J40,0) -> 0.11727154 | ... L21: =IFERROR(Historical_FS!L40,0) -> 0.099112858
B22: =Historical_FS!B45&" % Sales" -> Net Profit % Sales | C22: =IFERROR(Historical_FS!C46,0) -> 0.098580541 | D22: =IFERROR(Historical_FS!D46,0) -> 0.10693661 | E22: =IFERROR(Historical_FS!E46,0) -> 0.071806297 | F22: =IFERROR(Historical_FS!F46,0) -> 0.05789313 | G22: =IFERROR(Historical_FS!G46,0) -> 0.13553841 | H22: =IFERROR(Historical_FS!H46,0) -> 0.12211855 | I22: =IFERROR(Historical_FS!I46,0) -> 0.1394377 | J22: =IFERROR(Historical_FS!J46,0) -> 0.080224567 | ... L22: =IFERROR(Historical_FS!L46,0) -> 0.079515893
A24: # | B24: Balance Sheet % Total Assets
B25: =Historical_FS!B80&" % Total Assets" -> Total Assets % Total Assets | C25: =IFERROR(Historical_FS!C80/Historical_FS!C80,0) -> 1 | D25: =IFERROR(Historical_FS!D80/Historical_FS!D80,0) -> 1 | E25: =IFERROR(Historical_FS!E80/Historical_FS!E80,0) -> 1 | F25: =IFERROR(Historical_FS!F80/Historical_FS!F80,0) -> 1 | G25: =IFERROR(Historical_FS!G80/Historical_FS!G80,0) -> 1 | H25: =IFERROR(Historical_FS!H80/Historical_FS!H80,0) -> 1 | I25: =IFERROR(Historical_FS!I80/Historical_FS!I80,0) -> 1 | J25: =IFERROR(Historical_FS!J80/Historical_FS!J80,0) -> 1 | ... L25: =IFERROR(Historical_FS!L80/Historical_FS!L80,0) -> 1
B27: =Historical_FS!B68&" % Total Assets" -> Net Block % Total Assets | C27: =IFERROR(Historical_FS!C68/Historical_FS!C$80,0) -> 0.61440906 | D27: =IFERROR(Historical_FS!D68/Historical_FS!D$80,0) -> 0.61370045 | E27: =IFERROR(Historical_FS!E68/Historical_FS!E$80,0) -> 0.69503924 | F27: =IFERROR(Historical_FS!F68/Historical_FS!F$80,0) -> 0.74020707 | G27: =IFERROR(Historical_FS!G68/Historical_FS!G$80,0) -> 0.72147723 | H27: =IFERROR(Historical_FS!H68/Historical_FS!H$80,0) -> 0.64300252 | I27: =IFERROR(Historical_FS!I68/Historical_FS!I$80,0) -> 0.66205246 | J27: =IFERROR(Historical_FS!J68/Historical_FS!J$80,0) -> 0.65198883 | ... L27: =IFERROR(Historical_FS!L68/Historical_FS!L$80,0) -> 0.7076462
B28: =Historical_FS!B69&" % Total Assets" -> Capital Work in Progress % Total Assets | C28: =IFERROR(Historical_FS!C69/Historical_FS!C$80,0) -> 0.035663488 | D28: =IFERROR(Historical_FS!D69/Historical_FS!D$80,0) -> 0.021831306 | E28: =IFERROR(Historical_FS!E69/Historical_FS!E$80,0) -> 0.026446993 | F28: =IFERROR(Historical_FS!F69/Historical_FS!F$80,0) -> 0.01507108 | G28: =IFERROR(Historical_FS!G69/Historical_FS!G$80,0) -> 0.011608961 | H28: =IFERROR(Historical_FS!H69/Historical_FS!H$80,0) -> 0.019572423 | I28: =IFERROR(Historical_FS!I69/Historical_FS!I$80,0) -> 0.057088507 | J28: =IFERROR(Historical_FS!J69/Historical_FS!J$80,0) -> 0.044215061 | ... L28: =IFERROR(Historical_FS!L69/Historical_FS!L$80,0) -> 0.046651904
B29: =Historical_FS!B70&" % Total Assets" -> Investments % Total Assets | C29: =IFERROR(Historical_FS!C70/Historical_FS!C$80,0) -> 0.1236901 | D29: =IFERROR(Historical_FS!D70/Historical_FS!D$80,0) -> 0.15850867 | E29: =IFERROR(Historical_FS!E70/Historical_FS!E$80,0) -> 0.095323698 | F29: =IFERROR(Historical_FS!F70/Historical_FS!F$80,0) -> 0.03817466 | G29: =IFERROR(Historical_FS!G70/Historical_FS!G$80,0) -> 0.074844146 | H29: =IFERROR(Historical_FS!H70/Historical_FS!H$80,0) -> 0.14131615 | I29: =IFERROR(Historical_FS!I70/Historical_FS!I$80,0) -> 0.075595527 | J29: =IFERROR(Historical_FS!J70/Historical_FS!J$80,0) -> 0.079852463 | ... L29: =IFERROR(Historical_FS!L70/Historical_FS!L$80,0) -> 0.038587073
B30: =Historical_FS!B71&" % Total Assets" -> Other Assets % Total Assets | C30: =IFERROR(Historical_FS!C71/Historical_FS!C$80,0) -> 0.064808654 | D30: =IFERROR(Historical_FS!D71/Historical_FS!D$80,0) -> 0.054179299 | E30: =IFERROR(Historical_FS!E71/Historical_FS!E$80,0) -> 0.083309401 | F30: =IFERROR(Historical_FS!F71/Historical_FS!F$80,0) -> 0.10689827 | G30: =IFERROR(Historical_FS!G71/Historical_FS!G$80,0) -> 0.10235703 | H30: =IFERROR(Historical_FS!H71/Historical_FS!H$80,0) -> 0.096345459 | I30: =IFERROR(Historical_FS!I71/Historical_FS!I$80,0) -> 0.097564962 | J30: =IFERROR(Historical_FS!J71/Historical_FS!J$80,0) -> 0.096690538 | ... L30: =IFERROR(Historical_FS!L71/Historical_FS!L$80,0) -> 0.078952835
B31: =Historical_FS!B72&" % Total Assets" -> Total Non Current Assets % Total Assets | C31: =IFERROR(Historical_FS!C72/Historical_FS!C$80,0) -> 0.8385713 | D31: =IFERROR(Historical_FS!D72/Historical_FS!D$80,0) -> 0.84821973 | E31: =IFERROR(Historical_FS!E72/Historical_FS!E$80,0) -> 0.90011934 | F31: =IFERROR(Historical_FS!F72/Historical_FS!F$80,0) -> 0.90035109 | G31: =IFERROR(Historical_FS!G72/Historical_FS!G$80,0) -> 0.91028736 | H31: =IFERROR(Historical_FS!H72/Historical_FS!H$80,0) -> 0.90023655 | I31: =IFERROR(Historical_FS!I72/Historical_FS!I$80,0) -> 0.89230146 | J31: =IFERROR(Historical_FS!J72/Historical_FS!J$80,0) -> 0.87274689 | ... L31: =IFERROR(Historical_FS!L72/Historical_FS!L$80,0) -> 0.87183802
B32: =Historical_FS!B75&" % Total Assets" -> Receivables % Total Assets | C32: =IFERROR(Historical_FS!C75/Historical_FS!C$80,0) -> 0.046809042 | D32: =IFERROR(Historical_FS!D75/Historical_FS!D$80,0) -> 0.041628217 | E32: =IFERROR(Historical_FS!E75/Historical_FS!E$80,0) -> 0.038862227 | F32: =IFERROR(Historical_FS!F75/Historical_FS!F$80,0) -> 0.036419687 | G32: =IFERROR(Historical_FS!G75/Historical_FS!G$80,0) -> 0.030085916 | H32: =IFERROR(Historical_FS!H75/Historical_FS!H$80,0) -> 0.029842642 | I32: =IFERROR(Historical_FS!I75/Historical_FS!I$80,0) -> 0.036649054 | J32: =IFERROR(Historical_FS!J75/Historical_FS!J$80,0) -> 0.042317827 | ... L32: =IFERROR(Historical_FS!L75/Historical_FS!L$80,0) -> 0.04407812
B33: =Historical_FS!B76&" % Total Assets" -> Inventory % Total Assets | C33: =IFERROR(Historical_FS!C76/Historical_FS!C$80,0) -> 0.059587149 | D33: =IFERROR(Historical_FS!D76/Historical_FS!D$80,0) -> 0.056874926 | E33: =IFERROR(Historical_FS!E76/Historical_FS!E$80,0) -> 0.057184593 | F33: =IFERROR(Historical_FS!F76/Historical_FS!F$80,0) -> 0.053563413 | G33: =IFERROR(Historical_FS!G76/Historical_FS!G$80,0) -> 0.052810867 | H33: =IFERROR(Historical_FS!H76/Historical_FS!H$80,0) -> 0.046624973 | I33: =IFERROR(Historical_FS!I76/Historical_FS!I$80,0) -> 0.066763917 | J33: =IFERROR(Historical_FS!J76/Historical_FS!J$80,0) -> 0.072355013 | ... L33: =IFERROR(Historical_FS!L76/Historical_FS!L$80,0) -> 0.071562019
B34: =Historical_FS!B77&" % Total Assets" -> Cash & Bank % Total Assets | C34: =IFERROR(Historical_FS!C77/Historical_FS!C$80,0) -> 0.055032504 | D34: =IFERROR(Historical_FS!D77/Historical_FS!D$80,0) -> 0.053277124 | E34: =IFERROR(Historical_FS!E77/Historical_FS!E$80,0) -> 0.0038338436 | F34: =IFERROR(Historical_FS!F77/Historical_FS!F$80,0) -> 0.0096658141 | G34: =IFERROR(Historical_FS!G77/Historical_FS!G$80,0) -> 0.006815857 | H34: =IFERROR(Historical_FS!H77/Historical_FS!H$80,0) -> 0.023295835 | I34: =IFERROR(Historical_FS!I77/Historical_FS!I$80,0) -> 0.0042855725 | J34: =IFERROR(Historical_FS!J77/Historical_FS!J$80,0) -> 0.012580269 | ... L34: =IFERROR(Historical_FS!L77/Historical_FS!L$80,0) -> 0.012521845
B35: =Historical_FS!B78&" % Total Assets" -> Total Current Assets % Total Assets | C35: =IFERROR(Historical_FS!C78/Historical_FS!C$80,0) -> 0.1614287 | D35: =IFERROR(Historical_FS!D78/Historical_FS!D$80,0) -> 0.15178027 | E35: =IFERROR(Historical_FS!E78/Historical_FS!E$80,0) -> 0.099880664 | F35: =IFERROR(Historical_FS!F78/Historical_FS!F$80,0) -> 0.099648914 | G35: =IFERROR(Historical_FS!G78/Historical_FS!G$80,0) -> 0.08971264 | H35: =IFERROR(Historical_FS!H78/Historical_FS!H$80,0) -> 0.09976345 | I35: =IFERROR(Historical_FS!I78/Historical_FS!I$80,0) -> 0.10769854 | J35: =IFERROR(Historical_FS!J78/Historical_FS!J$80,0) -> 0.12725311 | ... L35: =IFERROR(Historical_FS!L78/Historical_FS!L$80,0) -> 0.12816198
A37: # | B37: Balance Sheet % Total Liabilities
B38: Total Liabilities | C38: =IFERROR(Historical_FS!C63+Historical_FS!C64,0) -> 19247.48 | D38: =IFERROR(Historical_FS!D63+Historical_FS!D64,0) -> 17817.22 | E38: =IFERROR(Historical_FS!E63+Historical_FS!E64,0) -> 30759.93 | F38: =IFERROR(Historical_FS!F63+Historical_FS!F64,0) -> 42774.72 | G38: =IFERROR(Historical_FS!G63+Historical_FS!G64,0) -> 40170.05 | H38: =IFERROR(Historical_FS!H63+Historical_FS!H64,0) -> 42001.67 | I38: =IFERROR(Historical_FS!I63+Historical_FS!I64,0) -> 33376.17 | J38: =IFERROR(Historical_FS!J63+Historical_FS!J64,0) -> 37055.86 | ... L38: =IFERROR(Historical_FS!L63+Historical_FS!L64,0) -> 62925.29
B39: =B38&" % Total Liabilities" -> Total Liabilities % Total Liabilities | C39: =IFERROR(C38/C38,0) -> 1 | D39: =IFERROR(D38/D38,0) -> 1 | E39: =IFERROR(E38/E38,0) -> 1 | F39: =IFERROR(F38/F38,0) -> 1 | G39: =IFERROR(G38/G38,0) -> 1 | H39: =IFERROR(H38/H38,0) -> 1 | I39: =IFERROR(I38/I38,0) -> 1 | J39: =IFERROR(J38/J38,0) -> 1 | ... L39: =IFERROR(L38/L38,0) -> 1
B41: =Historical_FS!B61&" % Total Liabilities" -> Equity Share Capital % Total Liabilities | C41: =IFERROR(Historical_FS!C61/Vertical!C$38,0) -> 0.01425797 | D41: =IFERROR(Historical_FS!D61/Vertical!D$38,0) -> 0.015407005 | E41: =IFERROR(Historical_FS!E61/Vertical!E$38,0) -> 0.0089275236 | F41: =IFERROR(Historical_FS!F61/Vertical!F$38,0) -> 0.0064206148 | G41: =IFERROR(Historical_FS!G61/Vertical!G$38,0) -> 0.0071852039 | H41: =IFERROR(Historical_FS!H61/Vertical!H$38,0) -> 0.0068723458 | I41: =IFERROR(Historical_FS!I61/Vertical!I$38,0) -> 0.0086489852 | J41: =IFERROR(Historical_FS!J61/Vertical!J$38,0) -> 0.0077906706 | ... L41: =IFERROR(Historical_FS!L61/Vertical!L$38,0) -> 0.0046830138
B42: =Historical_FS!B62&" % Total Liabilities" -> Reserves % Total Liabilities | C42: =IFERROR(Historical_FS!C62/Vertical!C$38,0) -> 1.125924 | D42: =IFERROR(Historical_FS!D62/Vertical!D$38,0) -> 1.3535995 | E42: =IFERROR(Historical_FS!E62/Vertical!E$38,0) -> 0.84871942 | F42: =IFERROR(Historical_FS!F62/Vertical!F$38,0) -> 0.78261202 | G42: =IFERROR(Historical_FS!G62/Vertical!G$38,0) -> 0.96477674 | H42: =IFERROR(Historical_FS!H62/Vertical!H$38,0) -> 1.0448639 | I42: =IFERROR(Historical_FS!I62/Vertical!I$38,0) -> 1.5024672 | J42: =IFERROR(Historical_FS!J62/Vertical!J$38,0) -> 1.4582268 | ... L42: =IFERROR(Historical_FS!L62/Vertical!L$38,0) -> 1.1189792
B43: =Historical_FS!B63&" % Total Liabilities" -> Borrowings % Total Liabilities | C43: =IFERROR(Historical_FS!C63/Vertical!C$38,0) -> 0.5515522 | D43: =IFERROR(Historical_FS!D63/Vertical!D$38,0) -> 0.47563481 | E43: =IFERROR(Historical_FS!E63/Vertical!E$38,0) -> 0.63329858 | F43: =IFERROR(Historical_FS!F63/Vertical!F$38,0) -> 0.59233585 | G43: =IFERROR(Historical_FS!G63/Vertical!G$38,0) -> 0.57303787 | H43: =IFERROR(Historical_FS!H63/Vertical!H$38,0) -> 0.51710777 | I43: =IFERROR(Historical_FS!I63/Vertical!I$38,0) -> 0.33852896 | J43: =IFERROR(Historical_FS!J63/Vertical!J$38,0) -> 0.29840732 | ... L43: =IFERROR(Historical_FS!L63/Vertical!L$38,0) -> 0.38302851
B44: =Historical_FS!B64&" % Total Liabilities" -> Other Liabilities % Total Liabilities | C44: =IFERROR(Historical_FS!C64/Vertical!C$38,0) -> 0.4484478 | D44: =IFERROR(Historical_FS!D64/Vertical!D$38,0) -> 0.52436519 | E44: =IFERROR(Historical_FS!E64/Vertical!E$38,0) -> 0.36670142 | F44: =IFERROR(Historical_FS!F64/Vertical!F$38,0) -> 0.40766415 | G44: =IFERROR(Historical_FS!G64/Vertical!G$38,0) -> 0.42696213 | H44: =IFERROR(Historical_FS!H64/Vertical!H$38,0) -> 0.48289223 | I44: =IFERROR(Historical_FS!I64/Vertical!I$38,0) -> 0.66147104 | J44: =IFERROR(Historical_FS!J64/Vertical!J$38,0) -> 0.70159268 | ... L44: =IFERROR(Historical_FS!L64/Vertical!L$38,0) -> 0.61697149

Sheet Horizontal
B9: ="Horizontal Analysis"&" - "&'Data Sheet'!B1 -> Horizontal Analysis - ULTRATECH CEMENT LTD
B10: Years | C10: ='Data Sheet'!B16 -> 42460 | D10: ='Data Sheet'!C16 -> 42825 | E10: ='Data Sheet'!D16 -> 43190 | F10: ='Data Sheet'!E16 -> 43555 | G10: ='Data Sheet'!F16 -> 43921 | H10: ='Data Sheet'!G16 -> 44286 | I10: ='Data Sheet'!H16 -> 44651 | J10: ='Data Sheet'!I16 -> 45016 | ... L10: ='Data Sheet'!K16 -> 45747 | M10: Trend
A11: # | B11: Income Statement YoY Growth
B13: =Historical_FS!B12 -> Sales | C13: =IFERROR(Historical_FS!C12,0) -> 25153.24 | D13: =IFERROR(Historical_FS!D12,0) -> 25374.94 | E13: =IFERROR(Historical_FS!E12,0) -> 30978.62 | F13: =IFERROR(Historical_FS!F12,0) -> 41462.26 | G13: =IFERROR(Historical_FS!G12,0) -> 42429.89 | H13: =IFERROR(Historical_FS!H12,0) -> 44725.8 | I13: =IFERROR(Historical_FS!I12,0) -> 52598.83 | J13: =IFERROR(Historical_FS!J12,0) -> 63239.98 | ... L13: =IFERROR(Historical_FS!L12,0) -> 75955.13
B14: =B13&" Growth" -> Sales Growth | C14: =IFERROR((C13/B13)-1,"-") -> - | D14: =IFERROR((D13/C13)-1,"-") -> 0.0088139739 | E14: =IFERROR((E13/D13)-1,"-") -> 0.2208352 | F14: =IFERROR((F13/E13)-1,"-") -> 0.33841533 | G14: =IFERROR((G13/F13)-1,"-") -> 0.023337609 | H14: =IFERROR((H13/G13)-1,"-") -> 0.054110675 | I14: =IFERROR((I13/H13)-1,"-") -> 0.17602882 | J14: =IFERROR((J13/I13)-1,"-") -> 0.20230773 | ... L14: =IFERROR((L13/K13)-1,"-") -> 0.071176454
B15: =Historical_FS!B18 -> COGS | C15: =IFERROR(Historical_FS!C18,0) -> 12397.13 | D15: =IFERROR(Historical_FS!D18,0) -> 12303.62 | E15: =IFERROR(Historical_FS!E18,0) -> 15744.19 | F15: =IFERROR(Historical_FS!F18,0) -> 21729.72 | G15: =IFERROR(Historical_FS!G18,0) -> 20600.87 | H15: =IFERROR(Historical_FS!H18,0) -> 20847.7 | I15: =IFERROR(Historical_FS!I18,0) -> 26536.92 | J15: =IFERROR(Historical_FS!J18,0) -> 35301.93 | ... L15: =IFERROR(Historical_FS!L18,0) -> 41216.74
B16: =B15&" Growth" -> COGS Growth | C16: =IFERROR((C15/B15)-1,"-") -> - | D16: =IFERROR((D15/C15)-1,"-") -> -0.0075428748 | E16: =IFERROR((E15/D15)-1,"-") -> 0.27963884 | F16: =IFERROR((F15/E15)-1,"-") -> 0.38017389 | G16: =IFERROR((G15/F15)-1,"-") -> -0.051949588 | H16: =IFERROR((H15/G15)-1,"-") -> 0.011981533 | I16: =IFERROR((I15/H15)-1,"-") -> 0.27289437 | J16: =IFERROR((J15/I15)-1,"-") -> 0.33029492 | ... L16: =IFERROR((L15/K15)-1,"-") -> 0.080771651
B17: =Historical_FS!B21 -> Gross Profit | C17: =IFERROR(Historical_FS!C21,0) -> 13219.92 | D17: =IFERROR(Historical_FS!D21,0) -> 13719.44 | E17: =IFERROR(Historical_FS!E21,0) -> 15476.4 | F17: =IFERROR(Historical_FS!F21,0) -> 20082.64 | G17: =IFERROR(Historical_FS!G21,0) -> 22480.08 | H17: =IFERROR(Historical_FS!H21,0) -> 24496.62 | I17: =IFERROR(Historical_FS!I21,0) -> 26731.34 | J17: =IFERROR(Historical_FS!J21,0) -> 28445.16 | ... L17: =IFERROR(Historical_FS!L21,0) -> 35135.13
B18: =B17&" Growth" -> Gross Profit Growth | C18: =IFERROR((C17/B17)-1,"-") -> - | D18: =IFERROR((D17/C17)-1,"-") -> 0.037785403 | E18: =IFERROR((E17/D17)-1,"-") -> 0.12806354 | F18: =IFERROR((F17/E17)-1,"-") -> 0.29762994 | G18: =IFERROR((G17/F17)-1,"-") -> 0.11937873 | H18: =IFERROR((H17/G17)-1,"-") -> 0.089703417 | I18: =IFERROR((I17/H17)-1,"-") -> 0.091225647 | J18: =IFERROR((J17/I17)-1,"-") -> 0.064112761 | ... L18: =IFERROR((L17/K17)-1,"-") -> 0.054200434
